2023-03-26 22:22:17,448 INFO    StreamThr :148478 [internal.py:wandb_internal():87] W&B internal server running at pid: 148478, started at: 2023-03-26 22:22:17.447571
2023-03-26 22:22:17,453 DEBUG   HandlerThread:148478 [handler.py:handle_request():144] handle_request: status
2023-03-26 22:22:17,458 INFO    WriterThread:148478 [datastore.py:open_for_write():85] open: /home/cognitron/kogivid/wandb/run-20230326_222217-otuf43jd/run-otuf43jd.wandb
2023-03-26 22:22:17,461 DEBUG   SenderThread:148478 [sender.py:send():336] send: header
2023-03-26 22:22:17,462 DEBUG   SenderThread:148478 [sender.py:send():336] send: run
2023-03-26 22:22:18,211 ERROR   SenderThread:148478 [internal_api.py:execute():246] 401 response executing GraphQL.
2023-03-26 22:22:18,212 ERROR   SenderThread:148478 [internal_api.py:execute():247] {"errors":[{"message":"user is not logged in","path":["upsertBucket"],"extensions":{"code":"PERMISSION_ERROR"}}],"data":{"upsertBucket":null}}
2023-03-26 22:22:18,212 ERROR   SenderThread:148478 [sender.py:send_run():931] The API key is either invalid or missing, or the host is incorrect. To resolve this issue, you may try running the 'wandb login --host [hostname]' command. The host defaults to 'https://api.wandb.ai' if not specified. (Error 401: Unauthorized)
Traceback (most recent call last):
  File "/home/cognitron/.local/lib/python3.10/site-packages/wandb/sdk/lib/retry.py", line 131, in __call__
    result = self._call_fn(*args, **kwargs)
  File "/home/cognitron/.local/lib/python3.10/site-packages/wandb/sdk/internal/internal_api.py", line 243, in execute
    return self.client.execute(*args, **kwargs)  # type: ignore
  File "/home/cognitron/.local/lib/python3.10/site-packages/wandb/vendor/gql-0.2.0/wandb_gql/client.py", line 52, in execute
    result = self._get_result(document, *args, **kwargs)
  File "/home/cognitron/.local/lib/python3.10/site-packages/wandb/vendor/gql-0.2.0/wandb_gql/client.py", line 60, in _get_result
    return self.transport.execute(document, *args, **kwargs)
  File "/home/cognitron/.local/lib/python3.10/site-packages/wandb/vendor/gql-0.2.0/wandb_gql/transport/requests.py", line 39, in execute
    request.raise_for_status()
  File "/home/cognitron/.local/lib/python3.10/site-packages/requests/models.py", line 1021, in raise_for_status
    raise HTTPError(http_error_msg, response=self)
requests.exceptions.HTTPError: 401 Client Error: Unauthorized for url: https://api.wandb.ai/graphql

During handling of the above exception, another exception occurred:

Traceback (most recent call last):
  File "/home/cognitron/.local/lib/python3.10/site-packages/wandb/sdk/internal/sender.py", line 929, in send_run
    self._init_run(run, config_value_dict)
  File "/home/cognitron/.local/lib/python3.10/site-packages/wandb/sdk/internal/sender.py", line 968, in _init_run
    server_run, inserted, server_messages = self._api.upsert_run(
  File "/home/cognitron/.local/lib/python3.10/site-packages/wandb/apis/normalize.py", line 51, in wrapper
    raise err
  File "/home/cognitron/.local/lib/python3.10/site-packages/wandb/apis/normalize.py", line 25, in wrapper
    return func(*args, **kwargs)
  File "/home/cognitron/.local/lib/python3.10/site-packages/wandb/sdk/internal/internal_api.py", line 1664, in upsert_run
    response = self.gql(
  File "/home/cognitron/.local/lib/python3.10/site-packages/wandb/sdk/internal/internal_api.py", line 215, in gql
    ret = self._retry_gql(
  File "/home/cognitron/.local/lib/python3.10/site-packages/wandb/sdk/lib/retry.py", line 147, in __call__
    retry_timedelta_triggered = check_retry_fn(e)
  File "/home/cognitron/.local/lib/python3.10/site-packages/wandb/util.py", line 1092, in check_retry_fn
    return fallback_retry_fn(e)
  File "/home/cognitron/.local/lib/python3.10/site-packages/wandb/util.py", line 1025, in no_retry_auth
    raise CommError(
wandb.errors.CommError: The API key is either invalid or missing, or the host is incorrect. To resolve this issue, you may try running the 'wandb login --host [hostname]' command. The host defaults to 'https://api.wandb.ai' if not specified. (Error 401: Unauthorized)
2023-03-26 22:22:18,274 DEBUG   HandlerThread:148478 [handler.py:handle_request():144] handle_request: shutdown
2023-03-26 22:22:18,274 INFO    HandlerThread:148478 [handler.py:finish():842] shutting down handler
2023-03-26 22:22:18,460 INFO    WriterThread:148478 [datastore.py:close():298] close: /home/cognitron/kogivid/wandb/run-20230326_222217-otuf43jd/run-otuf43jd.wandb
2023-03-26 22:22:19,218 INFO    SenderThread:148478 [sender.py:finish():1504] shutting down sender
